Workbook

Sheet BHE nodes
A1: Well Location Calculation
A4: Well Position X | B4: 0 | C4: m
A5: Well Position Y | B5: 0 | C5: m
A6: Borehole Radius | B6: 0.15 | C6: m
A9: n nodes | B9: 6
A10: distance factor | B10: =EXP(2*PI()/(B9*TAN(PI()/B9))) -> 6.1337074
A11: node distance | B11: =B10*B6 -> 0.92005611 | C11: m
C12: Data Table for 6 nodes
A14: Center X | B14: Center Y | C14: ID | D14: X | E14: Y | F14: comment
A15: =$B$4 -> 0 | B15: =$B$5 -> 0 | C15: 0 | D15: =A15 -> 0 | E15: =B15 -> 0 | F15: =IF(C15>$B$9+1,"delete node","")
A16: =$B$4 -> 0 | B16: =$B$5 -> 0 | C16: =B7+1 -> 1 | D16: =A16+SIN((C16-2.5)*2*PI()/$B$9)*$B$11 -> -0.92005611 | E16: =B16+COS((C16-2.5)*2*PI()/$B$9)*$B$11 -> 5.6337189e-17 | F16: =IF(C16>$B$9+1,"delete node","")
A17: =$B$4 -> 0 | B17: =$B$5 -> 0 | C17: =C16+1 -> 2 | D17: =A17+SIN((C17-2.5)*2*PI()/$B$9)*$B$11 -> -0.46002806 | E17: =B17+COS((C17-2.5)*2*PI()/$B$9)*$B$11 -> 0.79679196 | F17: =IF(C17>$B$9+1,"delete node","")
A18: =$B$4 -> 0 | B18: =$B$5 -> 0 | C18: =C17+1 -> 3 | D18: =A18+SIN((C18-2.5)*2*PI()/$B$9)*$B$11 -> 0.46002806 | E18: =B18+COS((C18-2.5)*2*PI()/$B$9)*$B$11 -> 0.79679196 | F18: =IF(C18>$B$9+1,"delete node","")
A19: =$B$4 -> 0 | B19: =$B$5 -> 0 | C19: =C18+1 -> 4 | D19: =A19+SIN((C19-2.5)*2*PI()/$B$9)*$B$11 -> 0.92005611 | E19: =B19+COS((C19-2.5)*2*PI()/$B$9)*$B$11 -> 5.6337189e-17 | F19: =IF(C19>$B$9+1,"delete node","")
A20: =$B$4 -> 0 | B20: =$B$5 -> 0 | C20: =C19+1 -> 5 | D20: =A20+SIN((C20-2.5)*2*PI()/$B$9)*$B$11 -> 0.46002806 | E20: =B20+COS((C20-2.5)*2*PI()/$B$9)*$B$11 -> -0.79679196 | F20: =IF(C20>$B$9+1,"delete node","")
A21: =$B$4 -> 0 | B21: =$B$5 -> 0 | C21: =C20+1 -> 6 | D21: =A21+SIN((C21-2.5)*2*PI()/$B$9)*$B$11 -> -0.46002806 | E21: =B21+COS((C21-2.5)*2*PI()/$B$9)*$B$11 -> -0.79679196 | F21: =IF(C21>$B$9+1,"delete node","")
C22: END
C24: > export to pnt

Sheet wellnodecoordinates
A1: mesh node ID | B1: X | C1: Y | E1: node ID | F1: Est | G1: Nord | I1: Well ID | J1: Est | K1: Nord
A2: 100 | B2: =SUMIF($I$2:$I$11,$A2,J$2:J$11) -> 3000 | C2: =SUMIF($I$2:$I$11,$A2,K$2:K$11) -> 4000 | E2: ='BHE nodes'!C15 -> 0 | F2: =ROUND('BHE nodes'!D15,3) -> 0 | G2: =ROUND('BHE nodes'!E15,3) -> 0 | I2: 100 | J2: 3000 | K2: 4000
A3: 101 | B3: =$B$2+F3 -> 2999.08 | C3: =$C$2+G3 -> 4000 | E3: ='BHE nodes'!C16 -> 1 | F3: =ROUND('BHE nodes'!D16,3) -> -0.92 | G3: =ROUND('BHE nodes'!E16,3) -> 0 | I3: =I2+100 -> 200 | J3: 3000 | K3: 4250
A4: 102 | B4: =$B$2+F4 -> 2999.54 | C4: =$C$2+G4 -> 4000.797 | E4: ='BHE nodes'!C17 -> 2 | F4: =ROUND('BHE nodes'!D17,3) -> -0.46 | G4: =ROUND('BHE nodes'!E17,3) -> 0.797 | I4: =I3+100 -> 300 | J4: 3000 | K4: 3750
A5: 103 | B5: =$B$2+F5 -> 3000.46 | C5: =$C$2+G5 -> 4000.797 | E5: ='BHE nodes'!C18 -> 3 | F5: =ROUND('BHE nodes'!D18,3) -> 0.46 | G5: =ROUND('BHE nodes'!E18,3) -> 0.797 | I5: =I4+100 -> 400 | J5: 2750 | K5: 4000
A6: 104 | B6: =$B$2+F6 -> 3000.92 | C6: =$C$2+G6 -> 4000 | E6: ='BHE nodes'!C19 -> 4 | F6: =ROUND('BHE nodes'!D19,3) -> 0.92 | G6: =ROUND('BHE nodes'!E19,3) -> 0 | I6: =I5+100 -> 500 | J6: 3250 | K6: 4000
A7: 105 | B7: =$B$2+F7 -> 3000.46 | C7: =$C$2+G7 -> 3999.203 | E7: ='BHE nodes'!C20 -> 5 | F7: =ROUND('BHE nodes'!D20,3) -> 0.46 | G7: =ROUND('BHE nodes'!E20,3) -> -0.797 | I7: =I6+100 -> 600 | J7: 5000 | K7: 4000
A8: 106 | B8: =$B$2+F8 -> 2999.54 | C8: =$C$2+G8 -> 3999.203 | E8: ='BHE nodes'!C21 -> 6 | F8: =ROUND('BHE nodes'!D21,3) -> -0.46 | G8: =ROUND('BHE nodes'!E21,3) -> -0.797 | I8: =I7+100 -> 700 | J8: 5000 | K8: 4250
A9: =A2+100 -> 200 | B9: =SUMIF($I$2:$I$11,$A9,J$2:J$11) -> 3000 | C9: =SUMIF($I$2:$I$11,$A9,K$2:K$11) -> 4250 | I9: =I8+100 -> 800 | J9: 5000 | K9: 3750
A10: =A3+100 -> 201 | B10: =B$9+F3 -> 2999.08 | C10: =C$9+G3 -> 4250 | I10: =I9+100 -> 900 | J10: 4750 | K10: 4000
A11: =A4+100 -> 202 | B11: =B$9+F4 -> 2999.54 | C11: =C$9+G4 -> 4250.797 | I11: =I10+100 -> 1000 | J11: 5250 | K11: 4000
A12: =A5+100 -> 203 | B12: =B$9+F5 -> 3000.46 | C12: =C$9+G5 -> 4250.797
A13: =A6+100 -> 204 | B13: =B$9+F6 -> 3000.92 | C13: =C$9+G6 -> 4250
A14: =A7+100 -> 205 | B14: =B$9+F7 -> 3000.46 | C14: =C$9+G7 -> 4249.203
A15: =A8+100 -> 206 | B15: =B$9+F8 -> 2999.54 | C15: =C$9+G8 -> 4249.203
A16: =A9+100 -> 300 | B16: =SUMIF($I$2:$I$11,$A16,J$2:J$11) -> 3000 | C16: =SUMIF($I$2:$I$11,$A16,K$2:K$11) -> 3750
A17: =A10+100 -> 301 | B17: =B$16+F3 -> 2999.08 | C17: =C$16+G3 -> 3750
A18: =A11+100 -> 302 | B18: =B$16+F4 -> 2999.54 | C18: =C$16+G4 -> 3750.797
A19: =A12+100 -> 303 | B19: =B$16+F5 -> 3000.46 | C19: =C$16+G5 -> 3750.797
A20: =A13+100 -> 304 | B20: =B$16+F6 -> 3000.92 | C20: =C$16+G6 -> 3750
A21: =A14+100 -> 305 | B21: =B$16+F7 -> 3000.46 | C21: =C$16+G7 -> 3749.203
A22: =A15+100 -> 306 | B22: =B$16+F8 -> 2999.54 | C22: =C$16+G8 -> 3749.203
A23: =A16+100 -> 400 | B23: =SUMIF($I$2:$I$11,$A23,J$2:J$11) -> 2750 | C23: =SUMIF($I$2:$I$11,$A23,K$2:K$11) -> 4000
A24: =A17+100 -> 401 | B24: =B$23+F3 -> 2749.08 | C24: =C$23+G3 -> 4000
A25: =A18+100 -> 402 | B25: =B$23+F4 -> 2749.54 | C25: =C$23+G4 -> 4000.797
A26: =A19+100 -> 403 | B26: =B$23+F5 -> 2750.46 | C26: =C$23+G5 -> 4000.797
A27: =A20+100 -> 404 | B27: =B$23+F6 -> 2750.92 | C27: =C$23+G6 -> 4000
A28: =A21+100 -> 405 | B28: =B$23+F7 -> 2750.46 | C28: =C$23+G7 -> 3999.203
A29: =A22+100 -> 406 | B29: =B$23+F8 -> 2749.54 | C29: =C$23+G8 -> 3999.203
A30: =A23+100 -> 500 | B30: =SUMIF($I$2:$I$11,$A30,J$2:J$11) -> 3250 | C30: =SUMIF($I$2:$I$11,$A30,K$2:K$11) -> 4000
A31: =A24+100 -> 501 | B31: =B$30+F3 -> 3249.08 | C31: =C$30+G3 -> 4000
A32: =A25+100 -> 502 | B32: =B$30+F4 -> 3249.54 | C32: =C$30+G4 -> 4000.797
A33: =A26+100 -> 503 | B33: =B$30+F5 -> 3250.46 | C33: =C$30+G5 -> 4000.797
A34: =A27+100 -> 504 | B34: =B$30+F6 -> 3250.92 | C34: =C$30+G6 -> 4000
A35: =A28+100 -> 505 | B35: =B$30+F7 -> 3250.46 | C35: =C$30+G7 -> 3999.203
A36: =A29+100 -> 506 | B36: =B$30+F8 -> 3249.54 | C36: =C$30+G8 -> 3999.203
A37: =A30+100 -> 600 | B37: =SUMIF($I$2:$I$11,$A37,J$2:J$11) -> 5000 | C37: =SUMIF($I$2:$I$11,$A37,K$2:K$11) -> 4000
A38: =A31+100 -> 601 | B38: =B$37+F3 -> 4999.08 | C38: =C$37+G3 -> 4000
A39: =A32+100 -> 602 | B39: =B$37+F4 -> 4999.54 | C39: =C$37+G4 -> 4000.797
A40: =A33+100 -> 603 | B40: =B$37+F5 -> 5000.46 | C40: =C$37+G5 -> 4000.797
...

Sheet welldata
A1: Well ID | B1: X | C1: Y | D1: depth top | E1: depth bottom | F1: radius | G1: rate
A2: =CONCATENATE("prod-",wellnodecoordinates!I2/100) -> prod-1 | B2: =wellnodecoordinates!J2 -> 3000 | C2: =wellnodecoordinates!K2 -> 4000 | D2: 870 | E2: 1120 | F2: 0.15 | G2: 30
A3: =CONCATENATE("prod-",wellnodecoordinates!I3/100) -> prod-2 | B3: =wellnodecoordinates!J3 -> 3000 | C3: =wellnodecoordinates!K3 -> 4250 | D3: 870 | E3: 1120 | F3: 0.15 | G3: 30
A4: =CONCATENATE("prod-",wellnodecoordinates!I4/100) -> prod-3 | B4: =wellnodecoordinates!J4 -> 3000 | C4: =wellnodecoordinates!K4 -> 3750 | D4: 870 | E4: 1120 | F4: 0.15 | G4: 30
A5: =CONCATENATE("prod-",wellnodecoordinates!I5/100) -> prod-4 | B5: =wellnodecoordinates!J5 -> 2750 | C5: =wellnodecoordinates!K5 -> 4000 | D5: 870 | E5: 1120 | F5: 0.15 | G5: 30
A6: =CONCATENATE("prod-",wellnodecoordinates!I6/100) -> prod-5 | B6: =wellnodecoordinates!J6 -> 3250 | C6: =wellnodecoordinates!K6 -> 4000 | D6: 870 | E6: 1120 | F6: 0.15 | G6: 30
A7: =CONCATENATE("inj-",wellnodecoordinates!I7/100-5) -> inj-1 | B7: =wellnodecoordinates!J7 -> 5000 | C7: =wellnodecoordinates!K7 -> 4000 | D7: 870 | E7: 1120 | F7: 0.15 | G7: -30
A8: =CONCATENATE("inj-",wellnodecoordinates!I8/100-5) -> inj-2 | B8: =wellnodecoordinates!J8 -> 5000 | C8: =wellnodecoordinates!K8 -> 4250 | D8: 870 | E8: 1120 | F8: 0.15 | G8: -30
A9: =CONCATENATE("inj-",wellnodecoordinates!I9/100-5) -> inj-3 | B9: =wellnodecoordinates!J9 -> 5000 | C9: =wellnodecoordinates!K9 -> 3750 | D9: 870 | E9: 1120 | F9: 0.15 | G9: -30
A10: =CONCATENATE("inj-",wellnodecoordinates!I10/100-5) -> inj-4 | B10: =wellnodecoordinates!J10 -> 4750 | C10: =wellnodecoordinates!K10 -> 4000 | D10: 870 | E10: 1120 | F10: 0.15 | G10: -30
A11: =CONCATENATE("inj-",wellnodecoordinates!I11/100-5) -> inj-5 | B11: =wellnodecoordinates!J11 -> 5250 | C11: =wellnodecoordinates!K11 -> 4000 | D11: 870 | E11: 1120 | F11: 0.15 | G11: -30

Sheet Tinj
A1: Well ID | B1: X | C1: Y | D1: Tinj
A2: =welldata!A7 -> inj-1 | B2: =welldata!B7 -> 5000 | C2: =welldata!C7 -> 4000 | D2: 50
A3: =welldata!A8 -> inj-2 | B3: =welldata!B8 -> 5000 | C3: =welldata!C8 -> 4250 | D3: 50
A4: =welldata!A9 -> inj-3 | B4: =welldata!B9 -> 5000 | C4: =welldata!C9 -> 3750 | D4: 50
A5: =welldata!A10 -> inj-4 | B5: =welldata!B10 -> 4750 | C5: =welldata!C10 -> 4000 | D5: 50
A6: =welldata!A11 -> inj-5 | B6: =welldata!B11 -> 5250 | C6: =welldata!C11 -> 4000 | D6: 50

Sheet conductivities
A1: slice | B1: k (m2) | C1: K (m/s) @10°C | D1: K (m/d) @10°C | E1: K (m/s) @135°C | H1: 10°C | I1: 135°C
A2: 1 | B2: 1.243e-15 | C2: =B2*$H$3*9.81/$H$2 -> 1.0884079e-08 | D2: =C2*86400 -> 0.00094038445 | E2: =B2*$I$3*9.81/$I$2 -> 6.6674087e-08 | G2: viscosity | H2: 0.00112 | I2: 0.0001807
A3: 2,3,4 | B3: 9.133e-14 | C3: =B3*$H$3*9.81/$H$2 -> 7.9971276e-07 | D3: =C3*86400 -> 0.069095183 | E3: =B3*$I$3*9.81/$I$2 -> 4.8989094e-06 | G3: density | H3: 999.69975 | I3: 988.04128
A4: 5,6 | B4: 7.226e-16 | C4: =B4*$H$3*9.81/$H$2 -> 6.3273014e-09 | D4: =C4*86400 -> 0.00054667885 | E4: =B4*$I$3*9.81/$I$2 -> 3.8760012e-08

Sheet sliceT
A1: Slice | B1: Tinit | C1: Depth
A2: 1 | B2: 15 | C2: 0
A3: 2 | B3: 134.13 | C3: 870
A4: 3 | B4: 144.61 | C4: 970
A5: 4 | B5: 155.09 | C5: 1070
A6: 5 | B6: 160.33 | C6: 1120
A7: 6 | B7: 258.31 | C7: 3100
